<?xml version="1.0"?>
<robot xmlns:xacro="http://www.ros.org/wiki/xacro" >

    <xacro:include filename="inertial_macros.xacro" />
    <material name="white">
        <color rgba="1 1 1 1" />
    </material>

    <material name="orange">
        <color rgba="1 0.3 0.1 1"/>
    </material>

    <material name="blue">
        <color rgba="0.2 0.2 1 1"/>
    </material>

    <material name="black">
        <color rgba="0 0 0 1"/>
    </material>

    <material name="red">
        <color rgba="1 0 0 1"/>
    </material>

    <material name="pink">
            <color rgba="1 0.5 0.5 1"/>
    </material>

    <material name="lightblue">
            <color rgba="0.7 0.7 1 1"/>
    </material>

    <material name="yellow">
            <color rgba="1 1 0 1"/>
    </material>


    <!-- BASE LINK -->

    <link name="base_link">

    </link>

    <joint name="chassis_joint" type="fixed">
        <parent link="base_link"/>
        <child link="chassis"/>
        <origin xyz="0 0 0"/>
        <dynamics damping="1" friction="1"/>
    </joint>

    <gazebo reference="chassis">
        <material>Gazebo/Orange</material>
    </gazebo>

    <!-- CHASSIS body -->
    
    <link name="chassis">
        <visual>
            <origin xyz="0 0 1.69" rpy="0 0 ${pi/2}"/>
            <geometry>
                <mesh filename="file:///home/yuu/project_robot_y2_ws/src/articubot_one/description/final_robot_main.dae" scale = "1 1 1"/>
            </geometry>
            <material name="yellow"/>
        </visual>
        <collision>
            <origin xyz="0 0 1.69" rpy="0 0 ${pi/2}"/>
            <geometry>
                <mesh filename="file:///home/yuu/project_robot_y2_ws/src/articubot_one/description/final_robot_main.dae" scale = "1 1 1"/>
            </geometry>
        </collision>
        <!-- ... visual and collision here ... -->
        <xacro:inertial_box mass="3" x="0.05" y="0.05" z="0.15">
            <origin xyz="1 1 1" rpy="0 0 0"/>
        </xacro:inertial_box>
    </link>

    <!-- BASE_FOOTPRINT LINK -->

    <joint name="base_footprint_joint" type="fixed">
        <parent link="base_link"/>
        <child link="base_footprint"/>
        <origin xyz="0 0 0" rpy="0 0 0"/>
    </joint>

    <link name="base_footprint">
    </link>


    <!-- LEFT FRONT WHEEL -->

    <joint name="left_front_wheel_joint" type="continuous">
        <parent link="base_link"/>
        <child link="left_front_wheel"/>
        <origin xyz="2.1 0.19 1" rpy="0 0 ${pi/2} "/>
        <axis xyz="0 -1 0"/>
        <!-- axis = แกนหมุน -->
        <dynamics damping="1" friction="1"/>
    </joint>

    <link name="left_front_wheel">
        <visual>
            <geometry>
                <mesh filename="file:///home/yuu/project_robot_y2_ws/src/articubot_one/description/final_robot_wheel.dae" scale = "1 1 1"/>
            </geometry>
            <material name="red"/>
        </visual>
        <collision>
            <geometry>
                <mesh filename="file:///home/yuu/project_robot_y2_ws/src/articubot_one/description/final_robot_wheel.dae" scale = "1 1 1"/>
            </geometry>
        </collision>
        <!-- ... visual and collision here ... -->
        <xacro:inertial_cylinder mass="0.5" length="0.02" radius="0.05">
            <origin xyz="1 1 1" rpy="${pi/2} ${pi/2} 0"/>
        </xacro:inertial_cylinder>
    </link>
    <gazebo reference="left_front_wheel">
        <material>Gazebo/Blue</material>
        <mu1 value="0.1"/>
        <mu2 value="0.1"/>
    </gazebo>

    <!-- LEFT BACK WHEEL -->

    <joint name="left_back_wheel_joint" type="continuous">
        <parent link="base_link"/>
        <child link="left_back_wheel"/>
        <origin xyz="2.1 2.67 1" rpy="0 0 ${pi/2} "/>
        <axis xyz="0 -1 0"/>
        <!-- axis = แกนหมุน -->
        <dynamics damping="1" friction="1"/>
    </joint>

    <link name="left_back_wheel">
        <visual>
            <geometry>
                <mesh filename="file:///home/yuu/project_robot_y2_ws/src/articubot_one/description/final_robot_wheel.dae" scale = "1 1 1"/>
            </geometry>
            <material name="red"/>
        </visual>
        <collision>
            <geometry>
                <mesh filename="file:///home/yuu/project_robot_y2_ws/src/articubot_one/description/final_robot_wheel.dae" scale = "1 1 1"/>
            </geometry>
        </collision>
        <!-- ... visual and collision here ... -->
        <xacro:inertial_cylinder mass="0.5" length="0.02" radius="0.05">
            <origin xyz="1 1 1" rpy="${pi/2} ${pi/2} 0"/>
        </xacro:inertial_cylinder>
    </link>
    <gazebo reference="left_back_wheel">
        <material>Gazebo/Blue</material>
        <mu1 value="0.1"/>
        <mu2 value="0.1"/>
    </gazebo>

    <!-- RIGHT FRONT WHEEL -->

    <joint name="right_front_wheel_joint" type="continuous">
        <parent link="base_link"/>
        <child link="right_front_wheel"/>
        <origin xyz="-2.1 0.19 1" rpy="0 0 -${pi/2} "/>
        <axis xyz="0 1 0"/>
        <!-- axis = แกนหมุน -->
        <dynamics damping="1" friction="1"/>
    </joint>

    <link name="right_front_wheel">
        <visual>
            <geometry>
                <mesh filename="file:///home/yuu/project_robot_y2_ws/src/articubot_one/description/final_robot_wheel.dae" scale = "1 1 1"/>
            </geometry>
            <material name="red"/>
        </visual>
        <collision>
            <geometry>
                <mesh filename="file:///home/yuu/project_robot_y2_ws/src/articubot_one/description/final_robot_wheel.dae" scale = "1 1 1"/>
            </geometry>
        </collision>
        <!-- ... visual and collision here ... -->
        <xacro:inertial_cylinder mass="0.5" length="0.02" radius="0.05">
            <origin xyz="1 1 1" rpy="${pi/2} ${pi/2} 0"/>
        </xacro:inertial_cylinder>
    </link>
    <gazebo reference="right_front_wheel">
        <material>Gazebo/Blue</material>
        <mu1 value="0.1"/>
        <mu2 value="0.1"/>
    </gazebo>

    <!-- RIGHT BACK WHEEL -->

    <joint name="right_back_wheel_joint" type="continuous">
        <parent link="base_link"/>
        <child link="right_back_wheel"/>
        <origin xyz="-2.1 2.67 1" rpy="0 0 -${pi/2} "/>
        <axis xyz="0 1 0"/>
        <!-- axis = แกนหมุน -->
        <dynamics damping="1" friction="1"/>
    </joint>

    <link name="right_back_wheel">
        <visual>
            <geometry>
                <mesh filename="file:///home/yuu/project_robot_y2_ws/src/articubot_one/description/final_robot_wheel.dae" scale = "1 1 1"/>
            </geometry>
            <material name="red"/>
        </visual>
        <collision>
            <geometry>
                <mesh filename="file:///home/yuu/project_robot_y2_ws/src/articubot_one/description/final_robot_wheel.dae" scale = "1 1 1"/>
            </geometry>
        </collision>
        <!-- ... visual and collision here ... -->
        <xacro:inertial_cylinder mass="0.5" length="0.02" radius="0.05">
            <origin xyz="1 1 1" rpy="${pi/2} ${pi/2} 0"/>
        </xacro:inertial_cylinder>
    </link>
    <gazebo reference="right_back_wheel">
        <material>Gazebo/Blue</material>
        <mu1 value="0.1"/>
        <mu2 value="0.1"/>
    </gazebo>

    <!-- Arm Joint 1 -->
    <joint name="arm_1_joint" type="revolute">
        <parent link="chassis"/>
        <child link="arm_1"/>
        <origin xyz="0 -1.19 3.83" rpy="0 0 ${pi/2}"/>
        <axis xyz="0 1 0"/>
        <limit lower = "-0.5" upper = "2.5" effort = "0.5" velocity="0.5" />
        <dynamics damping="1" friction="1"/>
    </joint>

    <link name="arm_1">
        <visual>
            <geometry>
                <mesh filename="file:///home/yuu/project_robot_y2_ws/src/articubot_one/description/final_robot_joint1.dae" scale = "1 1 1"/>
            </geometry>
        </visual>
        <collision>
            <geometry>
                <mesh filename="file:///home/yuu/project_robot_y2_ws/src/articubot_one/description/final_robot_joint1.dae" scale = "1 1 1"/>
            </geometry>
        </collision>
        <xacro:inertial_cylinder mass="0.05" length="0.01" radius="0.01">
            <origin xyz="1 1 1" rpy="0 0 0"/>
        </xacro:inertial_cylinder>
    </link>

    <gazebo reference="arm_1">
        <material>Gazebo/Orange</material>
        <mu1 value="0.1"/>
        <mu2 value="0.1"/>
    </gazebo>

    <!-- Arm Joint 2 -->

    <joint name="arm_2_joint" type="revolute">
        <parent link="arm_1"/>
        <child link="arm_2"/>
        <origin xyz="-1.36 0 0.1" rpy="0 0 0"/>
        <axis xyz="0 1 0"/>
        <limit lower = "-0.1" upper = "2.0" effort = "0.5" velocity="0.5" />
        <dynamics damping="1" friction="1"/>
    </joint>

    <link name="arm_2">
        <visual>
            <geometry>
                <mesh filename="file:///home/yuu/project_robot_y2_ws/src/articubot_one/description/final_robot_joint2.dae" scale = "1 1 1"/>
            </geometry>
        </visual>
        <collision>
            <geometry>
                <mesh filename="file:///home/yuu/project_robot_y2_ws/src/articubot_one/description/final_robot_joint2.dae" scale = "1 1 1"/>
            </geometry>
        </collision>
        <xacro:inertial_cylinder mass="0.05" length="0.01" radius="0.01">
            <origin xyz="1 1 1" rpy="0 0 0"/>
        </xacro:inertial_cylinder>
    </link>

    <gazebo reference="arm_2">
        <material>Gazebo/Orange</material>
        <mu1 value="0.1"/>
        <mu2 value="0.1"/>
    </gazebo>

    <!-- Arm Joint 3 -->

    <joint name="arm_3_joint" type="revolute">
        <parent link="arm_2"/>
        <child link="arm_3"/>
        <origin xyz="-0.749 0 -1.385" rpy="0 0 0"/>
        <axis xyz="0 1 0"/>
        <limit lower = "0.3" upper = "1.7" effort = "0.5" velocity="0.5" />
        <dynamics damping="1" friction="1"/>
    </joint>

    <link name="arm_3">
        <visual>
            <geometry>
                <mesh filename="file:///home/yuu/project_robot_y2_ws/src/articubot_one/description/final_robot_joint3.dae" scale = "1 1 1"/>
            </geometry>
        </visual>
        <collision>
            <geometry>
                <mesh filename="file:///home/yuu/project_robot_y2_ws/src/articubot_one/description/final_robot_joint3.dae" scale = "1 1 1"/>
            </geometry>
        </collision>
        <xacro:inertial_cylinder mass="0.05" length="0.01" radius="0.01">
            <origin xyz="1 1 1" rpy="0 0 0"/>
        </xacro:inertial_cylinder>
    </link>

    <gazebo reference="arm_3">
        <material>Gazebo/Orange</material>
        <mu1 value="0.1"/>
        <mu2 value="0.1"/>
    </gazebo>

    <!-- GRIP -->
    <!-- Grip 1 -->

    <joint name="grip_1_joint" type="revolute">
        <parent link="arm_3"/>
        <child link="grip_1"/>
        <origin xyz="-0.012 -0.212 -0.392" rpy="0 0 0"/>
        <axis xyz="1 0 0"/>
        <limit lower = "0.4" upper = "-0.5" effort = "1" velocity="0.01" />
        <dynamics damping="1" friction="1"/>
    </joint>

    <link name="grip_1">
        <visual>
            <geometry>
                <mesh filename="file:///home/yuu/project_robot_y2_ws/src/articubot_one/description/final_robot_joint4.dae" scale = "1 1 1"/>
            </geometry>
        </visual>
        <collision>
            <geometry>
                <mesh filename="file:///home/yuu/project_robot_y2_ws/src/articubot_one/description/final_robot_joint4.dae" scale = "1 1 1"/>
            </geometry>
        </collision>
        <xacro:inertial_cylinder mass="0.05" length="0.01" radius="0.01">
            <origin xyz="1 1 1" rpy="0 0 0"/>
        </xacro:inertial_cylinder>
    </link>

    <gazebo reference="grip_1">
        <material>Gazebo/Red</material>
        <mu1 value="0.1"/>
        <mu2 value="0.1"/>
    </gazebo>

    <!-- Grip 2 -->

    <joint name="grip_2_joint" type="revolute">
        <parent link="arm_3"/>
        <child link="grip_2"/>
        <origin xyz="-0.012 0.212 -0.392" rpy="0 0 0"/>
        <axis xyz="1 0 0"/>
        <limit lower = "-0.4" upper = "0.5" effort = "1" velocity="0.01" />
        <dynamics damping="1" friction="1"/>
    </joint>

    <link name="grip_2">
        <visual>
            <geometry>
                <mesh filename="file:///home/yuu/project_robot_y2_ws/src/articubot_one/description/final_robot_joint5.dae" scale = "1 1 1"/>
            </geometry>
        </visual>
        <collision>
            <geometry>
                <mesh filename="file:///home/yuu/project_robot_y2_ws/src/articubot_one/description/final_robot_joint5.dae" scale = "1 1 1"/>
            </geometry>
        </collision>
        <xacro:inertial_cylinder mass="0.05" length="0.01" radius="0.01">
            <origin xyz="1 1 1" rpy="0 0 0"/>
        </xacro:inertial_cylinder>
    </link>

    <gazebo reference="grip_2">
        <material>Gazebo/Red</material>
        <mu1 value="0.1"/>
        <mu2 value="0.1"/>
    </gazebo>

</robot>